Workbook
Name _Toc308084624: 'Elementos Funcionales'!#REF!
Name OLE_LINK1: 'Costo Desarrollo'!#REF!

Sheet Elementos Funcionales
D1: Estimacion de Costos
D2: Proyecto 'RUTAS MTC' · RT-2026-001 — Sistema Web de Rutas Turísticas Peatonales desde Estaciones Ferroviarias
D4: MEDIDA DE TAMAÑO FUNCIONAL
A5: Puntos de función | D5: Nivel | E5: Clasificación | F5: Multiplicador (fijo) | G5: Numero de Elementos Funcionales (Auto) | H5: Descripción
A6: 1 | B6: Simple | D6: 1 | E6: Simple | F6: 1 | G6: =COUNTIF($E$15:$E$36,"=Simple") -> 3 | H6: Proceso funcional con hasta 3 operaciones lógicas, máximo 2 reglas de negocio, sin integraciones externas y manejo de 1 entidad de datos principal.
A7: 2 | B7: Promedio | D7: 2 | E7: Promedio | F7: 3 | G7: =COUNTIF($E$15:$E$36,"=Promedio") -> 9 | H7: Proceso funcional con 4 a 7 operaciones lógicas o hasta 5 reglas de negocio, o conexión con 1 sistema externo, y manejo de 2 a 3 entidades de datos.
A8: 3 | B8: Complejo | D8: 3 | E8: Complejo | F8: 6 | G8: =COUNTIF($E$15:$E$36,"=Complejo") -> 10 | H8: Proceso funcional con 8 a 15 operaciones lógicas o hasta 10 reglas de negocio, o conexión con 2 a 3 sistemas externos, y manejo de 4 a 6 entidades de datos.
A9: 4 | B9: Muy Complejo | D9: 4 | E9: Muy Complejo | F9: 8 | G9: =COUNTIF($E$15:$E$36,"=Muy Complejo") -> 0 | H9: Proceso funcional con más de 15 operaciones lógicas o más de 10 reglas de negocio, o conexión con 4 o más sistemas externos, o procesamiento masivo/crítico de información.
A10: TOTAL Puntos de Funcion | D10: TOTAL Tamaño Funcional | F10: =F6*G6+F7*G7+F8*G8+F9*G9 -> 90 | G10: =SUM(G6:G9) -> 22
A13: Casos de uso | B13: tipo | D13: Elementos Funcionales | E13: Categoría (Sel) | F13: Complejidad (Auto) | G13: Nombre del Elemento Funcional | I13: Clasificación
A14: Numero | B14: Tipo | D14: Numero | E14: Tipo | G14: ALCANCE DE PROYECTO
D15: 1 | E15: Simple | F15: =SUMIF(E$6:E$9,E15,F$6:F$9) -> 1 | G15: CU-RT-001 CONSULTAR CATÁLOGO PÚBLICO DE ESTACIONES (RF01) | I15: Consulta
D16: 2 | E16: Promedio | F16: =SUMIF(E$6:E$9,E16,F$6:F$9) -> 3 | G16: CU-RT-002 CONSULTAR ZONAS TURÍSTICAS POR ESTACIÓN (RF02) | I16: Consulta
D17: 3 | E17: Promedio | F17: =SUMIF(E$6:E$9,E17,F$6:F$9) -> 3 | G17: CU-RT-003 REGISTRAR PREFERENCIAS TURÍSTICAS (RF03) | I17: Registro
D18: 4 | E18: Promedio | F18: =SUMIF(E$6:E$9,E18,F$6:F$9) -> 3 | G18: CU-RT-004 SELECCIONAR ESTACIÓN DE PARTIDA (RF04) | I18: Consulta
D19: 5 | E19: Complejo | F19: =SUMIF(E$6:E$9,E19,F$6:F$9) -> 6 | G19: CU-RT-005 LISTAR ALTERNATIVAS COMPATIBLES (RF05) | I19: Proceso
D20: 6 | E20: Complejo | F20: =SUMIF(E$6:E$9,E20,F$6:F$9) -> 6 | G20: CU-RT-006 CALCULAR LA RUTA PEATONAL DE IDA Y VUELTA (RF06) | I20: Proceso
D21: 7 | E21: Complejo | F21: =SUMIF(E$6:E$9,E21,F$6:F$9) -> 6 | G21: CU-RT-007 CONSULTAR EL PRONÓSTICO CLIMÁTICO (RF07) | I21: Integración
D22: 8 | E22: Complejo | F22: =SUMIF(E$6:E$9,E22,F$6:F$9) -> 6 | G22: CU-RT-008 SINCRONIZAR AUTOMÁTICAMENTE EL CLIMA (RF08) | I22: Integración
D23: 9 | E23: Complejo | F23: =SUMIF(E$6:E$9,E23,F$6:F$9) -> 6 | G23: CU-RT-009 GENERAR EL INFORME TURÍSTICO CONSOLIDADO (RF09) | I23: Reporte
D24: 10 | E24: Simple | F24: =SUMIF(E$6:E$9,E24,F$6:F$9) -> 1 | G24: CU-RT-010 RECUPERAR UN INFORME POR SU CÓDIGO (RF10) | I24: Consulta
D25: 11 | E25: Complejo | F25: =SUMIF(E$6:E$9,E25,F$6:F$9) -> 6 | G25: CU-RT-011 AUTENTICAR A LOS OPERADORES DEL PANEL (RF11) | I25: Seguridad
D26: 12 | E26: Complejo | F26: =SUMIF(E$6:E$9,E26,F$6:F$9) -> 6 | G26: CU-RT-012 CONTROLAR EL ACCESO POR ROL (RF12) | I26: Seguridad
... D36: 22 | E36: Promedio | F36: =SUMIF(E$6:E$9,E36,F$6:F$9) -> 3 | G36: CU-RT-022 EXPORTAR EL INFORME A PDF (RF22) | I36: Reporte

Sheet Factores Complejidad Tecnica
I1: Teniendo en cuenta la relación Esfuerzo / Dificultad
B2: Factor Tecnico | D2: Multiplicador Constante | E2: Magnitud Relativa (Entre 0-5) | F2: Descripción
B3: 1 | C3: Sistema Distribuido | D3: 2 | E3: 4 | F3: La arquitectura de la solución puede ser centralizada o cliente servidor, o puede ser distribuido (como N-CAPAS) o multi-nivel. | G3: =D3*E3 -> 8 | I3: Magnitud Relativa (Entre 0-5) | J3: Categoria
B4: 2 | C4: Tiempo de Respuesta Eficaz | D4: 1 | E4: 4 | F4: La velocidad de respuesta para los usuarios es un importante factor (y no trivial). Por ejemplo, si la carga del servidor se espera que sea muy baja, esto puede ser un factor trivial. | G4: =D4*E4 -> 4 | I4: 0 | J4: Muy Bajo
B5: 3 | C5: Eficiencia del Usuario Final | D5: 1 | E5: 4 | F5: En la aplicación que se están desarrollando para optimizar la eficiencia del usuario, o simplemente la capacidad. | G5: =D5*E5 -> 4 | I5: 1 | J5: Bajo | Y5: X
B6: 4 | C6: Procesamiento interno Complejo necesario | D6: 1 | E6: 5 | F6: Hay mucha algorítmica de difícil trabajo para hacer y poner a prueba. | G6: =D6*E6 -> 5 | I6: 2 | J6: Nominal
B7: 5 | C7: Código reutilizable debe ser un foco | D7: 1 | E7: 4 | F7: ¿Es pesada la reutilización de código? Código reutilización reduce la cantidad de esfuerzo necesario para implementar un proyecto. También reduce la cantidad de tiempo necesario para depurar un proyecto. Una función de biblioteca compartida puede ser reutilizada varias veces. | G7: =D7*E7 -> 4 | I7: 3 | J7: Alto
B8: 6 | C8: Facilidad de instalación | D8: 0.5 | E8: 2 | F8: ¿Es la facilidad de instalación para los usuarios finales un factor clave? Cuanto más alto sea el nivel de competencia de los usuarios, menor es el número. | G8: =D8*E8 -> 1 | I8: 4 | J8: Muy Alto
B9: 7 | C9: Facilidad de Usabilidad | D9: 0.5 | E9: 5 | F9: ¿Es la facilidad de uso uno de los principales criterios para la aceptación? Cuanto mayor es la importancia de la facilidad de uso, mayor es el número. | G9: =D9*E9 -> 2.5 | I9: 5 | J9: Extremadamente Alto
B10: 8 | C10: Portabilidad | D10: 2 | E10: 3 | F10: ¿Se requiere soportar multi-plataforma? Múltiples tipos de plataformas tienen que ser soportadas. | G10: =D10*E10 -> 6
B11: 9 | C11: Fácil Modificación | D11: 1 | E11: 4 | F11: ¿El cliente requerirá la capacidad de cambiar o personalizar la aplicación en el futuro? Cuanto más cambio / adaptación que se requiere en el futuro, mayor es el valor. | G11: =D11*E11 -> 4
B12: 10 | C12: Altamente concurrente | D12: 1 | E12: 2 | F12: ¿Va a tener para hacer frente a la base de datos de bloqueo y otras cuestiones de concurrencia? Mientras mayor atención tiene que tener la solución a los conflictos en los datos o aplicación, se más alto es el valor. | G12: =D12*E12 -> 2 | K12: Magnitud | L12: Categoría | M12: Criterio de selección
B13: 11 | C13: Personalización de Seguridad | D13: 1 | E13: 4 | F13: ¿Es posible aprovechar soluciones de seguridad existentes o es necesario desarrollar código personalizado? Tradicionalmente, incorporar mecanismos de seguridad se ha asociado con un incremento del trabajo y la complejidad del desarrollo. | G13: =D13*E13 -> 4 | K13: 0 | L13: Muy Bajo | M13: La característica tiene presencia o exigencia mínima.
B14: 12 | C14: Dependencia de Terceros | D14: 1 | E14: 4 | F14: ¿La aplicación requiere el uso de controles o bibliotecas de terceros? Al igual que códigos reutilizables, el código de terceros puede reducir el esfuerzo necesario para implementar una solución. | G14: =D14*E14 -> 4 | K14: 1 | L14: Bajo | M14: La característica tiene poca presencia o exigencia.
B15: 13 | C15: Entrenamiento Especial | D15: 1 | E15: 2 | F15: ¿Cuánto cuesta la formación de los usuarios que se requiere? La aplicación es compleja, o el apoyo a actividades complejas? | G15: =D15*E15 -> 2 | K15: 2 | L15: Nominal | M15: La característica presenta un nivel normal o esperado.
B16: TOTAL FACTOR DE COMPLEJIDAD TECNICA | E16: {=0.6+(SUM(D3:D15*E3:E15)/100)} -> 1.105 | G16: =0.6+SUM(G3:G15)/100 -> 1.105 | K16: 3 | L16: Alto | M16: La característica presenta una presencia o exigencia importante.
K17: 4 | L17: Muy Alto | M17: La característica presenta una presencia o exigencia considerable.
K18: 5 | L18: Extremadamente Alto | M18: La característica presenta una presencia o exigencia excepcional.

Sheet Tabla cálculo LOC
A1: Tecnología | B1: Can. Líneas de código (LOC)
A2: LOC JAVA EFECTIVAS | B2: =E34 -> 9900
A3: LOC | B3: =B2/1000 -> 9.9
A5: Regla Práctica LOC por Tipo Funcional
A6: Tipo Funcional | B6: LOC Promedio (min-max) | D6: Qué Incluye
A7: Registro | B7: 200 | C7: 400 | D7: Formulario + validaciones + BD
A8: Consulta | B8: 150 | C8: 350 | D8: Búsqueda + filtros + visualización
A9: Proceso | B9: 400 | C9: 800 | D9: Reglas + cálculos + lógica
A10: Reporte | B10: 300 | C10: 600 | D10: Consultas + formato + exportación + generacion de documento
A11: Integracion | B11: 500 | C11: 1000 | D11: Comunicación + intercambio de datos + APIs/servicios
A12: Seguridad | B12: 500 | C12: 1000 | D12: Control acceso + auditoría + cifrado
A17: Tamaño General del Software basado en LOC
A18: Tamaño | B18: Rango LOC | D18: Nº Funcionalidades Aproximadas
A19: Muy Pequeño | B19: 1K | C19: 5K | D19: 5 – 15
A20: Pequeño | B20: 5K | C20: 15K | D20: 15 – 40
A21: Mediano | B21: 15K | C21: 40K | D21: 40 – 100
A22: Grande | B22: 40K | C22: 120K | D22: 100 – 300
A23: Muy Grande | B23: 120K | C23: 500K+ | D23: 300+
A26: Fórmula Conceptual de Estimación | J26: El LOC promedio es el valor representativo dentro del rango LOC de cada tipo funcional.
A27: Clasificación | B27: Contar funcionalidades | D27: LOC Promedio | E27: LOC
A28: Registro | B28: =COUNTIF('Elementos Funcionales'!$I$15:$I$36,"=Registro") -> 5 | D28: =(B7+C7)/2 -> 300 | E28: =B28*D28 -> 1500
A29: Proceso | B29: =COUNTIF('Elementos Funcionales'!$I$15:$I$36,"=Proceso") -> 5 | D29: =(B9+C9)/2 -> 600 | E29: =B29*D29 -> 3000
A30: Reporte | B30: =COUNTIF('Elementos Funcionales'!$I$15:$I$36,"=Reporte") -> 2 | D30: =(B10+C10)/2 -> 450 | E30: =B30*D30 -> 900
A31: Seguridad | B31: =COUNTIF('Elementos Funcionales'!$I$15:$I$36,"=Seguridad") -> 2 | D31: =(B12+C12)/2 -> 750 | E31: =B31*D31 -> 1500
A32: Consulta | B32: =COUNTIF('Elementos Funcionales'!$I$15:$I$36,"=Consulta") -> 6 | D32: =(B8+C8)/2 -> 250 | E32: =B32*D32 -> 1500
A33: Integración | B33: =COUNTIF('Elementos Funcionales'!$I$15:$I$36,"=Integración") -> 2 | D33: =(B11+C11)/2 -> 750 | E33: =B33*D33 -> 1500
D34: TOTAL LOC | E34: =SUM(E28:E33) -> 9900

Sheet Costo Desarrollo
A1: COCOMO II , para calculo de Meses Hombre, a partir de casos de uso y puntos funcionales, según la metodología o Métrica.
A4: El esfuerzo en meses hombre se calcula así:
A6: PM = A x (Tamaño) ** E
A8: Donde:
A9: PM= Esfuerzo en meses hombre
A10: A= Constante 2.94
A11: Tamaño= Puntos Función x (líneas código) / 1000
A12: Líneas código = | B12: ='Tabla cálculo LOC'!B3 -> 9.9 | C12: para programas en Java
A14: Puntos de Función = Casos Uso x Complejidad
A15: Complejidad: 1= Baja, 3=Media, 6=Alta 8+Muy alta
A17: E= Constante para complejidad del proyecto, para un proyecto medio es 0,98
A24: Desarrollos | O24: Cronograma
A25: Esfuerzo meses hombre | D25: Costo Real | O25: dias
A26: Estimación de esfuerzo APLICACIÓN COCOMO II | D26: Costo por perfil de recurso humano | E26: Cantidad RRHH | F26: Meses Diseño | G26: Meses Construcción | H26: Meses Pruebas | I26: Meses Implementación | J26: Total meses | K26: total m/h | L26: T_Costo mes (miles) | M26: Costo_Parcial (miles) | O26: d1 | P26: d2 | Q26: d3 | R26: d4 | S26: d5 | T26: d6 | U26: d7 | V26: d8 | W26: d9 | X26: d10 | Y26: d11 | Z26: d12 | AA26: d13 | AB26: d14 | AC26: d15 | AD26: d16 | AE26: d17 | AF26: d18 | AG26: d19 | AH26: d20
A27: Numero de Elementos Funcionales | B27: ='Elementos Funcionales'!G10 -> 22 | D27: Jefe de Proyecto (JP) | E27: 1 | F27: =COUNTIF($O$27:$AH$27,"=D")/$E$35 -> 0.05 | G27: =COUNTIF($O$27:$AH$27,"=C")/$E$35 -> 0.05 | H27: =COUNTIF($O$27:$AH$27,"=P")/$E$35 -> 0.05 | I27: =COUNTIF($O$27:$AH$27,"=I")/$E$35 -> 0.05 | J27: =SUM(F27:I27) -> 0.2 | K27: =E27*J27 -> 0.2 | L27: =J27*$B$35 -> 4140.7802 | M27: =K27*L27 -> 828.15604 | N27: JP | O27: D | U27: C | AA27: P | AC27: I
A28: Tamaño funcional estándar | B28: ='Elementos Funcionales'!F10 -> 90 | D28: Analista de Negocio (AN) | E28: 1 | F28: =COUNTIF($O$28:$AH$28,"=D")/$E$35 -> 0.1 | G28: =COUNTIF($O$28:$AH$28,"=C")/$E$35 -> 0.05 | H28: =COUNTIF($O$28:$AH$28,"=P")/$E$35 -> 0.05 | I28: =COUNTIF($O$28:$AH$28,"=I")/$E$35 -> 0.05 | J28: =SUM(F28:I28) -> 0.25 | K28: =E28*J28 -> 0.25 | L28: =J28*$B$35 -> 5175.9752 | M28: =K28*L28 -> 1293.9938 | N28: AN | O28: D | P28: D | S28: C | Z28: P | AC28: I
A29: Constante A | B29: 2.94 | D29: Arquitecto Software (AS) | E29: 1 | F29: =COUNTIF($O$29:$AH$29,"=D")/$E$35 -> 0.15 | G29: =COUNTIF($O$29:$AH$29,"=C")/$E$35 -> 0.05 | H29: =COUNTIF($O$29:$AH$29,"=P")/$E$35 -> 0 | I29: =COUNTIF($O$29:$AH$29,"=I")/$E$35 -> 0.1 | J29: =SUM(F29:I29) -> 0.3 | K29: =E29*J29 -> 0.3 | L29: =J29*$B$35 -> 6211.1703 | M29: =K29*L29 -> 1863.3511 | N29: AS | O29: D | P29: D | Q29: D | R29: C | AB29: I | AC29: I
A30: Líneas de código | B30: =B12 -> 9.9 | D30: Desarrollador (DES) | E30: 1 | F30: =COUNTIF($O$30:$AH$30,"=D")/$E$35 -> 0.1 | G30: =COUNTIF($O$30:$AH$30,"=C")/$E$35 -> 0.35 | H30: =COUNTIF($O$30:$AH$30,"=P")/$E$35 -> 0.05 | I30: =COUNTIF($O$30:$AH$30,"=I")/$E$35 -> 0.05 | J30: =SUM(F30:I30) -> 0.55 | K30: =E30*J30 -> 0.55 | L30: =J30*$B$35 -> 11387.145 | M30: =K30*L30 -> 6262.93 | N30: DES | P30: D | Q30: D | R30: C | S30: C | T30: C | U30: C | V30: C | W30: C | X30: C | Y30: P | AB30: I
A31: Constante complejidad E = | B31: ='Factores Complejidad Tecnica'!$E$16 -> 1.105 | D31: Asegurador de Calidad (AC) | E31: 1 | F31: =COUNTIF($O$31:$AH$31,"=D")/$E$35 -> 0.05 | G31: =COUNTIF($O$31:$AH$31,"=C")/$E$35 -> 0 | H31: =COUNTIF($O$31:$AH$31,"=P")/$E$35 -> 0.25 | I31: =COUNTIF($O$31:$AH$31,"=I")/$E$35 -> 0.05 | J31: =SUM(F31:I31) -> 0.35 | K31: =E31*J31 -> 0.35 | L31: =J31*$B$35 -> 7246.3653 | M31: =K31*L31 -> 2536.2279 | N31: AC | Q31: D | V31: P | W31: P | Y31: P | Z31: P | AA31: P | AB31: I
A32: Tamaño | B32: =B28*B30/1000 -> 0.891 | D32: Total | E32: =SUM(E27:E31) -> 5 | K32: =SUM(K27:K31) -> 1.65 | L32: T_C | M32: =SUM(M27:M31) -> 12784.659 | O32: D | P32: Diseño
A33: PM (total persona, mes)= | B33: =B29*POWER(B32,B31) -> 2.5879876 | O33: C | P33: Construcción
A34: Costo Hora desarrollo | B34: 50 | D34: 1 Mes | E34: 4 | F34: Semanas | O34: P | P34: Pruebas
A35: Valor estimado (referencia técnica) | B35: =B34*B33*E35*E37 -> 20703.901 | D35: 4 semanas | E35: 20 | F35: Dias | O35: I | P35: Implementacion
D36: 1 Semana | E36: 5 | F36: Dias
A37: El costo total aproximado del desarrollo del software, calculado usando el esfuerzo estimado en PM y el costo por hora de trabajo. | D37: 1 dia | E37: 8 | F37: Horas
D39: Unificación de Costos y Esfuerzo por Perfil
D41: Jefe de Proyecto (JP):
D42: Insumo (T_Costo mes): Tiene un valor de mercado de S/. 4,140.78 por un mes completo.
D43: Ejecución (Costo_Parcial): Debido a que el cronograma solo le asigna 4 días de labor (interviniendo 1 día en cada fase: Diseño, Construcción, Pruebas e Implementación), su esfuerzo es de 0.20 meses.
D44: Conclusión: Se termina pagando S/. 828.16, lo que demuestra que su costo se distribuye equitativamente de forma puntual a lo largo de todo el ciclo de vida del software para labores de supervisión y control.
D46: Analista de Negocio (AN):
D47: Insumo (T_Costo mes): Su tarifa base es de S/. 5,175.98 mensuales.
D48: Ejecución (Costo_Parcial): El cronograma le asigna 5 días de trabajo, con mayor peso al inicio (2 días en Diseño) y participaciones puntuales en el resto de fases, sumando 0.25 meses.
D49: Conclusión: Su costo final es de S/. 1,293.99, evidenciando que es un recurso clave al principio para definir las reglas del sistema y al final para validar la aceptación del producto.
D51: Arquitecto de Software (AS):
D52: Insumo (T_Costo mes): Posee una valoración mensual de S/. 6,211.17.
D53: Ejecución (Costo_Parcial): Se le asignan 6 días de trabajo, concentrados fuertemente al inicio (3 días de Diseño para definir la base de datos y arquitectura) y al final (2 días de Implementación para el despliegue en servidores), equivalentes a 0.30 meses.
... D64: Conclusión: Genera un costo parcial de S/. 2,536.23, demostrando una asignación estratégica para realizar pruebas tempranas y una validación exhaustiva (QA) antes del lanzamiento en vivo.
B67: Conclusión: | D67: Se debe cobrar el Costo Parcial Total (S/. 12,784.66) más un margen de utilidad y gastos operativos, tomando como referencia de validación los S/. 20,703.90 que estimó el modelo COCOMO II. Si el precio final con ganancia se acerca a la cifra de COCOMO II, la propuesta económica es técnicamente sólida y competitiva.
B75: Conclusión Técnico-Financiera: El Escenario de Déficit
...

Sheet Tablas
A2: Estimación de costos de software con puntos de casos de uso: factores técnicos
A4: Aplicación de numero de elementos funcionales para crear estimaciones de costos de software confiables. Lo que hace que los elementos funcionales sean diferentes es que permiten que la estimación del costo del proyecto ocurra mucho antes en el proceso. Esta técnica de estimación de costos fue desarrollada por Gustav Karner para Rational Software Corporation
A6: Factores técnicos
A7: Al aplicar cualquier técnica general de estimación de costos, debe tener en cuenta muchas variables. Cada proyecto de software es diferente, y si no tiene en cuenta esas diferencias, su estimación no será confiable. En el método de elementos funcionales hay 13 factores que deben ser considerados. No todos los factores tienen el mismo impacto potencial en la estimación de costos de un proyecto, por lo que cada factor tiene un multiplicador que representa los pesos relativos de los factores.
A8: Aquí están los 13 factores técnicos de estimación de elementos funcionales. Cada factor se enumera como Nombre (multiplicador) – Descripción. Para cada factor, asignará una magnitud relativa de 0 (irrelevante) a 5 (críticamente importante).
J10: Factor
A11: 1. Sistema distribuido requerido: la arquitectura de la solución puede ser centralizada o de un solo usuario, o puede ser distribuida (como una solución de n niveles) o multiusuario. Los números más altos representan una arquitectura más compleja. | J11: 2
A12: 2. El tiempo de respuesta es importante: la rapidez de respuesta para los usuarios es un factor importante (y no trivial). Por ejemplo, si se espera que la carga del servidor sea muy baja, esto puede ser un factor trivial. Los números más altos representan una importancia creciente del tiempo de respuesta (un motor de búsqueda tendría un número alto, un agregador diario de noticias tendría un número bajo). | J12: 1
A13: 3. Eficiencia del usuario final: ¿la aplicación se está desarrollando para optimizar la eficiencia del usuario o solo la capacidad? Los números más altos representan proyectos que dependen más de la aplicación para mejorar la eficiencia del usuario. | J13: 1
A14: 4. Se requiere procesamiento interno complejo: ¿hay mucho trabajo algorítmico difícil de hacer y probar? Los algoritmos complejos (nivelación de recursos, análisis de sistemas en el dominio del tiempo, cubos OLAP) tienen números más altos. Las consultas simples a la base de datos tendrían números bajos. | J14: 1
A15: 5. El código reutilizable debe ser un enfoque: ¿la reutilización de código pesado es un objetivo o una meta? La reutilización de código reduce la cantidad de esfuerzo necesario para implementar un proyecto. También reduce la cantidad de tiempo necesario para depurar un proyecto. Una función de biblioteca compartida se puede reutilizar varias veces y arreglar el código en un solo lugar puede resolver varios errores. Cuanto mayor sea el nivel de reutilización, menor será el número. | J15: 1
A16: 6. Facilidad de instalación: ¿es la facilidad de instalación para los usuarios finales un factor clave? Cuanto mayor sea el nivel de competencia de los usuarios , menor será el número. | J16: 0.5
A17: 7. Usabilidad: ¿Es la facilidad de uso un criterio principal para la aceptación? Cuanto mayor sea la importancia de la usabilidad , mayor será el número. | J17: 0.5
A18: 8. Soporte multiplataforma: ¿Se requiere soporte multiplataforma? Cuantas más plataformas deban ser compatibles (esto podría ser versiones de navegador, dispositivos móviles, etc. o Windows/OSX/Unix), mayor será el valor. | J18: 2
A19: 9. Fácil de cambiar: ¿el cliente requiere la capacidad de cambiar o personalizar la aplicación en el futuro? Cuantos más cambios/personalizaciones se requieran en el futuro, mayor será el valor. | J19: 1
A20: 10. Altamente concurrente: ¿tendrá que abordar el bloqueo de la base de datos y otros problemas de concurrencia? Cuanta más atención deba dedicar a resolver conflictos en los datos o la aplicación, mayor será el valor. | J20: 1
A21: 11. Seguridad personalizada: ¿Se pueden aprovechar las soluciones de seguridad existentes o se debe desarrollar un código personalizado? Cuanto más trabajo de seguridad personalizado tenga que hacer (nivel de campo, nivel de página o seguridad basada en funciones, por ejemplo), mayor será el valor. | J21: 1
A22: 12. Dependencia del código de terceros: ¿la aplicación requerirá el uso de controles o bibliotecas de terceros? Al igual que el código reutilizable, el código de terceros puede reducir el esfuerzo necesario para implementar una solución. Cuanto más código de terceros (y más fiable sea el código de terceros), menor será el número. | J22: 1
A23: 13. Capacitación de usuarios: ¿Cuánta capacitación de usuarios se requiere? ¿La aplicación es compleja o admite actividades complejas? Cuanto más tarden los usuarios en cruzar el umbral de succión (lograr un nivel de dominio del producto), mayor será el valor. | J23: 1

Sheet Clas_Elem_Funci
B1: CLASIFICACIÓN DE ELEMENTOS FUNCIONALES
B3: Clasificación | C3: Descripción Funcional | D3: Cuándo se Usa | E3: Palabras Clave Asociadas | F3: Ejemplos | G3: Impacto en Esfuerzo
B4: Registro | C4: Funcionalidad orientada al ingreso, modificación, configuración o parametrización de datos del sistema. | D4: Configuración del sistema, parametrización del negocio, carga de información. | E4: Configurar, Definir, Parametrizar, Registrar, Crear catálogo, Cargar datos, Asociar | F4: Configurar variables, Definir requisitos, Parametrizar modelos, Cargar información | G4: Bajo a Medio
B5: Consulta | C5: Funcionalidad orientada a la visualización o consulta de información sin modificar datos. | D5: Visualización de datos, búsqueda, filtros, revisión histórica. | E5: Consultar, Ver, Buscar, Visualizar, Listar, Mostrar | F5: Consultar estado de crédito, Ver historial, Buscar beneficiarios | G5: Bajo
B6: Proceso | C6: Funcionalidad que ejecuta lógica de negocio, cálculos, validaciones o evaluaciones automáticas. | D6: Cálculos, validaciones, evaluación de reglas, análisis de datos. | E6: Evaluar, Calcular, Validar, Procesar, Ejecutar, Analizar, Determinar, Estimar | F6: Calcular puntaje, Evaluar requisitos, Estimar financiamiento | G6: Medio a Alto
B7: Reporte | C7: Funcionalidad que genera salidas estructuradas o documentos formales del sistema. | D7: Generación de reportes, exportaciones, publicación de resultados. | E7: Generar reporte, Exportar, Publicar resultados, Descargar archivo, Emitir documento | F7: Reporte PDF, Exportar Excel, Publicar resultados comité | G7: Medio
B8: Integración | C8: Funcionalidad que permite comunicación automática con sistemas externos. | D8: Conexión con APIs, servicios externos, plataformas externas. | E8: Integrar, Sincronizar, Consumir API, Enviar a sistema externo, Conectar, Intercambiar datos | F8: Consulta API externa, Enviar datos a sistema externo | G8: Alto
B9: Seguridad | C9: Funcionalidad relacionada con control, auditoría, autenticación o trazabilidad del sistema. | D9: Control de accesos, auditoría, firma digital, trazabilidad. | E9: Auditoría, Firma electrónica, Control acceso, Validar identidad, Trazabilidad, Autenticación | F9: Firma electrónica, Log auditoría, Listas de control | G9: Alto
