Workbook

Sheet EVA
A2: Código: | C2: RT-2026-001
A3: Nombre del Proyecto | C3: Sistema Web de Rutas Turísticas Peatonales desde Estaciones Ferroviarias
A4: Aprobado por: | C4: Ing. Mg. Freddy Ferrari Fernández
A5: Nombre del archivo: | C5: DOC-REQ-RT-2026-001 – Norma IEEE 830 act. ISO/IEC/IEEE 29148.xlsx
A6: Nivel de confidencialidad: | C6: Media
A9: RF: | B9: RF01: Consultar catálogo público de estaciones
A11: Ponderación de las Características
B12: Necesario | C12: Completo | D12: Consistente | E12: Singular | F12: No ambiguo | G12: Factible | H12: Verificable | I12: Modificable | J12: Rastreable | K12: Total | L12: Peso ponderado definido
A13: Necesario | B13: - | C13: 5 | D13: 5 | E13: 10 | F13: 5 | G13: 5 | H13: 5 | I13: 10 | J13: 10 | K13: =SUM(B13:J13) -> 55 | L13: =K13/$K$22 -> 0.34310667
A14: Completo | B14: 0.2 | C14: - | D14: 1 | E14: 5 | F14: 1 | G14: 1 | H14: 1 | I14: 5 | J14: 5 | K14: =SUM(B14:J14) -> 19.2 | L14: =K14/$K$22 -> 0.11977542
A15: Consistente | B15: 0.2 | C15: 1 | D15: - | E15: 5 | F15: 1 | G15: 1 | H15: 1 | I15: 5 | J15: 5 | K15: =SUM(B15:J15) -> 19.2 | L15: =K15/$K$22 -> 0.11977542
A16: Singular | B16: 0.1 | C16: 0.2 | D16: 0.2 | E16: - | F16: 0.2 | G16: 0.2 | H16: 0.2 | I16: 1 | J16: 1 | K16: =SUM(B16:J16) -> 3.1 | L16: =K16/$K$22 -> 0.01933874
A17: No ambiguo | B17: 0.2 | C17: 1 | D17: 1 | E17: 5 | F17: - | G17: 1 | H17: 1 | I17: 5 | J17: 5 | K17: =SUM(B17:J17) -> 19.2 | L17: =K17/$K$22 -> 0.11977542
A18: Factible | B18: 0.2 | C18: 1 | D18: 1 | E18: 5 | F18: 1 | G18: - | H18: 1 | I18: 5 | J18: 5 | K18: =SUM(B18:J18) -> 19.2 | L18: =K18/$K$22 -> 0.11977542
A19: Verificable | B19: 0.2 | C19: 1 | D19: 1 | E19: 5 | F19: 1 | G19: 1 | H19: - | I19: 5 | J19: 5 | K19: =SUM(B19:J19) -> 19.2 | L19: =K19/$K$22 -> 0.11977542
A20: Modificable | B20: 0.1 | C20: 0.2 | D20: 0.2 | E20: 1 | F20: 0.2 | G20: 0.2 | H20: 0.2 | I20: - | J20: 1 | K20: =SUM(B20:J20) -> 3.1 | L20: =K20/$K$22 -> 0.01933874
A21: Rastreable | B21: 0.1 | C21: 0.2 | D21: 0.2 | E21: 1 | F21: 0.2 | G21: 0.2 | H21: 0.2 | I21: 1 | J21: - | K21: =SUM(B21:J21) -> 3.1 | L21: =K21/$K$22 -> 0.01933874
A22: Total | K22: =SUM(K13:K21) -> 160.3 | L22: =SUM(L13:L21) -> 1
A25: RF: | B25: RF02: Consultar zonas turísticas por estación
A27: Ponderación de las Características
B28: Necesario | C28: Completo | D28: Consistente | E28: Singular | F28: No ambiguo | G28: Factible | H28: Verificable | I28: Modificable | J28: Rastreable | K28: Total | L28: Peso ponderado definido
A29: Necesario | B29: - | C29: 5 | D29: 5 | E29: 10 | F29: 5 | G29: 5 | H29: 5 | I29: 10 | J29: 10 | K29: =SUM(B29:J29) -> 55 | L29: =K29/$K$38 -> 0.34310667
A30: Completo | B30: 0.2 | C30: - | D30: 1 | E30: 5 | F30: 1 | G30: 1 | H30: 1 | I30: 5 | J30: 5 | K30: =SUM(B30:J30) -> 19.2 | L30: =K30/$K$38 -> 0.11977542
A31: Consistente | B31: 0.2 | C31: 1 | D31: - | E31: 5 | F31: 1 | G31: 1 | H31: 1 | I31: 5 | J31: 5 | K31: =SUM(B31:J31) -> 19.2 | L31: =K31/$K$38 -> 0.11977542
A32: Singular | B32: 0.1 | C32: 0.2 | D32: 0.2 | E32: - | F32: 0.2 | G32: 0.2 | H32: 0.2 | I32: 1 | J32: 1 | K32: =SUM(B32:J32) -> 3.1 | L32: =K32/$K$38 -> 0.01933874
A33: No ambiguo | B33: 0.2 | C33: 1 | D33: 1 | E33: 5 | F33: - | G33: 1 | H33: 1 | I33: 5 | J33: 5 | K33: =SUM(B33:J33) -> 19.2 | L33: =K33/$K$38 -> 0.11977542
A34: Factible | B34: 0.2 | C34: 1 | D34: 1 | E34: 5 | F34: 1 | G34: - | H34: 1 | I34: 5 | J34: 5 | K34: =SUM(B34:J34) -> 19.2 | L34: =K34/$K$38 -> 0.11977542
A35: Verificable | B35: 0.2 | C35: 1 | D35: 1 | E35: 5 | F35: 1 | G35: 1 | H35: - | I35: 5 | J35: 5 | K35: =SUM(B35:J35) -> 19.2 | L35: =K35/$K$38 -> 0.11977542
A36: Modificable | B36: 0.1 | C36: 0.2 | D36: 0.2 | E36: 1 | F36: 0.2 | G36: 0.2 | H36: 0.2 | I36: - | J36: 1 | K36: =SUM(B36:J36) -> 3.1 | L36: =K36/$K$38 -> 0.01933874
A37: Rastreable | B37: 0.1 | C37: 0.2 | D37: 0.2 | E37: 1 | F37: 0.2 | G37: 0.2 | H37: 0.2 | I37: 1 | J37: - | K37: =SUM(B37:J37) -> 3.1 | L37: =K37/$K$38 -> 0.01933874
A38: Total | K38: =SUM(K29:K37) -> 160.3 | L38: =SUM(L29:L37) -> 1
A41: RF: | B41: RF03: Registrar preferencias turísticas
A43: Ponderación de las Características
B44: Necesario | C44: Completo | D44: Consistente | E44: Singular | F44: No ambiguo | G44: Factible | H44: Verificable | I44: Modificable | J44: Rastreable | K44: Total | L44: Peso ponderado definido
A45: Necesario | B45: - | C45: 5 | D45: 5 | E45: 10 | F45: 5 | G45: 5 | H45: 5 | I45: 10 | J45: 10 | K45: =SUM(B45:J45) -> 55 | L45: =K45/$K$54 -> 0.34310667
A46: Completo | B46: 0.2 | C46: - | D46: 1 | E46: 5 | F46: 1 | G46: 1 | H46: 1 | I46: 5 | J46: 5 | K46: =SUM(B46:J46) -> 19.2 | L46: =K46/$K$54 -> 0.11977542
A47: Consistente | B47: 0.2 | C47: 1 | D47: - | E47: 5 | F47: 1 | G47: 1 | H47: 1 | I47: 5 | J47: 5 | K47: =SUM(B47:J47) -> 19.2 | L47: =K47/$K$54 -> 0.11977542
A48: Singular | B48: 0.1 | C48: 0.2 | D48: 0.2 | E48: - | F48: 0.2 | G48: 0.2 | H48: 0.2 | I48: 1 | J48: 1 | K48: =SUM(B48:J48) -> 3.1 | L48: =K48/$K$54 -> 0.01933874
A49: No ambiguo | B49: 0.2 | C49: 1 | D49: 1 | E49: 5 | F49: - | G49: 1 | H49: 1 | I49: 5 | J49: 5 | K49: =SUM(B49:J49) -> 19.2 | L49: =K49/$K$54 -> 0.11977542
A50: Factible | B50: 0.2 | C50: 1 | D50: 1 | E50: 5 | F50: 1 | G50: - | H50: 1 | I50: 5 | J50: 5 | K50: =SUM(B50:J50) -> 19.2 | L50: =K50/$K$54 -> 0.11977542
...

Sheet GRÁFICOS
A1: PANEL DE GRÁFICOS · EVALUACIÓN DE REQUERIMIENTOS
A2: Sistema Web de Rutas Turísticas Peatonales desde Estaciones Ferroviarias · RT-2026-001 · Norma ISO/IEC/IEEE 29148
A3: Todos los gráficos están vinculados a las celdas: si cambias una puntuación en la hoja EVA, se actualizan solos.
A6: 1. Requerimientos por criterio ganador
A7: Cuántos RF gobierna cada característica de calidad.
A9: Criterio ganador | B9: RF
A10: Necesario | B10: =COUNTIF(EVA!$D$364:$D$385,A10) -> 11
A11: No ambiguo | B11: =COUNTIF(EVA!$D$364:$D$385,A11) -> 4
A12: Completo | B12: =COUNTIF(EVA!$D$364:$D$385,A12) -> 7
A16: 2. Requerimientos por prioridad IEEE 830
A17: Grado de necesidad declarado en la Documentación SCRUM.
A19: Prioridad | B19: RF
A20: Esencial | B20: =COUNTIF(EVA!$F$364:$F$385,A20) -> 19
A21: Condicional | B21: =COUNTIF(EVA!$F$364:$F$385,A21) -> 2
A22: Opcional | B22: =COUNTIF(EVA!$F$364:$F$385,A22) -> 1
A26: 3. Requerimientos por módulo del sistema
A27: Reparto funcional entre los cuatro módulos y lo transversal.
A29: Módulo | B29: RF
A30: Cliente | B30: =COUNTIF(EVA!$G$364:$G$385,A30) -> 6
A31: Administración | B31: =COUNTIF(EVA!$G$364:$G$385,A31) -> 9
A32: Integración | B32: =COUNTIF(EVA!$G$364:$G$385,A32) -> 3
A33: Informes | B33: =COUNTIF(EVA!$G$364:$G$385,A33) -> 3
A34: Transversal | B34: =COUNTIF(EVA!$G$364:$G$385,A34) -> 1
A38: 4. Peso AHP del criterio ganador por requerimiento
A39: Cuánto domina el criterio ganador dentro de cada matriz 9x9.
A41: RF | B41: Peso AHP | C41: Criterio ganador
A42: =EVA!$B$364 -> RF01 | B42: =EVA!$E$364 -> 0.34310667 | C42: =EVA!$D$364 -> Necesario
A43: =EVA!$B$365 -> RF02 | B43: =EVA!$E$365 -> 0.34310667 | C43: =EVA!$D$365 -> Necesario
A44: =EVA!$B$366 -> RF03 | B44: =EVA!$E$366 -> 0.34310667 | C44: =EVA!$D$366 -> Necesario
A45: =EVA!$B$367 -> RF04 | B45: =EVA!$E$367 -> 0.34310667 | C45: =EVA!$D$367 -> Necesario
A46: =EVA!$B$368 -> RF05 | B46: =EVA!$E$368 -> 0.34310667 | C46: =EVA!$D$368 -> Necesario
A47: =EVA!$B$369 -> RF06 | B47: =EVA!$E$369 -> 0.25252525 | C47: =EVA!$D$369 -> No ambiguo
A48: =EVA!$B$370 -> RF07 | B48: =EVA!$E$370 -> 0.25252525 | C48: =EVA!$D$370 -> No ambiguo
A49: =EVA!$B$371 -> RF08 | B49: =EVA!$E$371 -> 0.25252525 | C49: =EVA!$D$371 -> No ambiguo
A50: =EVA!$B$372 -> RF09 | B50: =EVA!$E$372 -> 0.34310667 | C50: =EVA!$D$372 -> Necesario
A51: =EVA!$B$373 -> RF10 | B51: =EVA!$E$373 -> 0.30607125 | C51: =EVA!$D$373 -> Completo
A52: =EVA!$B$374 -> RF11 | B52: =EVA!$E$374 -> 0.30607125 | C52: =EVA!$D$374 -> Completo
A53: =EVA!$B$375 -> RF12 | B53: =EVA!$E$375 -> 0.30607125 | C53: =EVA!$D$375 -> Completo
A54: =EVA!$B$376 -> RF13 | B54: =EVA!$E$376 -> 0.34310667 | C54: =EVA!$D$376 -> Necesario
A55: =EVA!$B$377 -> RF14 | B55: =EVA!$E$377 -> 0.34310667 | C55: =EVA!$D$377 -> Necesario
...

Sheet INICIO
A2: INICIO DEL PROYECTO
A3: Nombre del Proyecto | B3: Siglas del Proyecto
A4: Sistema Web de Rutas Turísticas Peatonales desde Estaciones Ferroviarias "RUTAS MTC" | B4: RT-2026-001
A5: Descripción del Proyecto: Qué, quién, cómo, cuándo y dónde?
A6: QUÉ: Plataforma web que actúa como asesor turístico especializado y entrega al ciudadano rutas diseñadas para recorrerse exclusivamente a pie desde las estaciones ferroviarias, bajo un modelo de trayecto único de ida y vuelta. QUIÉN: Proyecto dispuesto por el Ministerio de Transportes y Comunicaciones (MTC) y ejecutado por el equipo de proyecto. Las fuentes de información periódica son SENAMHI (clima), PeruRail (estaciones, horarios y tarifas) y Travel Group Perú (zonas turísticas). CÓMO: Bajo Scrum Vanilla (Scrum Guide 2020), con arquitectura MVC en capas: Angular 22 en el frontend, Node.js 20 con Express 5 en el backend y MySQL 8 normalizada en 3FN con prefijos. CUÁNDO: Del 03 al 17 de agosto de 2026, en 15 días (Sprint 0 + Sprint 1 + Sprint 2). DÓNDE: Perú. Corredor ferroviario del sur con 13 estaciones y 42 zonas turísticas cargadas.
A9: Definición del Producto del Proyecto: Descripción del producto, servicio o capacidad a generar.
A10: Plataforma web pública con panel administrativo por roles. Permite al turista definir sus preferencias, seleccionar su estación de partida, visualizar las zonas turísticas cercanas compatibles y obtener un informe consolidado con la ruta de ida y vuelta, el pronóstico climático y el servicio ferroviario con su tarifa, identificado con un folio único INF-AAAA-NNNNNN. El panel entrega tres perfiles: PeruRail administra estaciones, horarios y tarifas; Travel Group Perú administra zonas turísticas y sus hitos; y el gestor MTC supervisa todos los módulos y decide qué se publica. Ningún registro se elimina físicamente.
A14: Objetivos del Proyecto: Metas hacia las cuales se debe dirigir el trabajo del proyecto en términos de la triple restricción.
A15: Concepto | B15: Objetivos | C15: criterio de Éxito
A16: 1. Alcance | B16: Análisis, diseño, construcción y despliegue de la plataforma: Módulo de Integración de Datos, Módulo de Administración con CRUD por rol y panel de publicación, Módulo Cliente/Usuario Final con el planificador guiado y Módulo de Informes. Incluye base de datos en 3FN con prefijos, plan de pruebas, manual de usuario y manual de instalación. No contempla aplicación móvil nativa, pasarela de pago ni integración con los sistemas internos de venta de PeruRail. | C16: Aprobación de todos los entregables por el MTC, sin observaciones críticas pendientes.
A17: 2. Tiempo | B17: El proyecto debe terminar en el plazo estipulado, sin ampliaciones de cronograma. | C17: Concluir el proyecto en un plazo de 15 días (03 al 17 de agosto de 2026).
A18: 3. Costo | B18: El presupuesto del proyecto es de S/ 00 000,00 (no aplica en esta sesión: proyecto de carácter académico). | C18: No exceder el presupuesto proyectado inicialmente.
A20: Designación del especialista: analista de negocios.
A21: Categoría de Gestión | B21: Información del Perfil | C21: Detalles de Autoridad y Supervisión
A22: Identificación | B22: Nombre: Marcelo Tapia | C22: Especialista encargado del análisis de los procesos de negocio del turismo peatonal y de la integración de las tres fuentes de datos.
A23: Linea de Mando | B23: Reporta a: Jefe del Proyecto – Marcelo Tapia | C23: Nivel estratégico-funcional; canaliza al MTC la validación de los requerimientos levantados.
A24: Supervisa Operativa | B24: Supervisa a: Arquitecta de Software – Sharon Valera | C24: Control funcional sobre la traducción de los requerimientos a decisiones de diseño técnico.
A25: Niveles de Autoridad Analista de Negocios | B25: Responsabilidad Técnica: | C25: (1). Aprueba el informe de Requerimientos Funcionales (RF) y No Funcionales (RNF) priorizados bajo IEEE 830 actualizada a ISO/IEC/IEEE 29148. (2). Valida las reglas de negocio del planificador: trayecto único de ida y vuelta y filtrado por intereses, dificultad y tiempo. (3). Define el modelo de roles del panel y la separación entre baja lógica y publicación. (4). Valida el contenido y la estructura del informe turístico consolidado. (5). Aprueba los casos de uso y el diagrama de flujo antes de su paso a construcción.
A27: Designación del especialista: arquitecto de software.
A28: Categoría de Gestión | B28: Información del Perfil | C28: Detalles de Autoridad y Supervisión
A29: Identificación | B29: Nombre: Sharon Valera | C29: Responsable de diseñar la arquitectura técnica del sistema (MVC en capas, API REST y modelo de datos en 3FN).
A30: Linea de Mando | B30: Reporta a: Jefe del Proyecto – Marcelo Tapia | C30: Nivel táctico-técnico que alinea los requerimientos con la solución tecnológica.
A31: Supervisa Operativa | B31: Supervisa a: Desarrollador – Ricardo Yanapa | C31: Supervisa que el código respete la arquitectura por capas, los patrones y la convención de prefijos.
A32: Niveles de Autoridad del arquitecto de software. | B32: Responsabilidad Técnica: | C32: Define y aprueba la arquitectura lógica y física, valida los requerimientos no funcionales de rendimiento, seguridad y disponibilidad, aprueba el stack tecnológico y el esquema en 3FN, y supervisa que la verificación de roles se ejecute siempre en el servidor.
A34: Designación del especialista: desarrollador.
A35: Categoría de Gestión | B35: Información del Perfil | C35: Detalles de Autoridad y Supervisión
A36: Identificación | B36: Nombre: Ricardo Yanapa | C36: Responsable del desarrollo e implementación de los módulos del backend (API REST) y del frontend (SPA Angular).
A37: Linea de Mando | B37: Reporta a: Arquitecta de Software – Sharon Valera | C37: Nivel operativo técnico que recibe los lineamientos arquitectónicos y corrige las observaciones de calidad.
A38: Supervisa Operativa | B38: Supervisa a: No aplica (rol de ejecución individual) | C38: Rol de ejecución directa que colabora con el Asegurador de Calidad y con la Arquitecta de Software.
A39: Niveles de Autoridad del desarrollador | B39: Responsabilidad Técnica: | C39: Implementa el cálculo de la ruta de ida y vuelta y su línea de tiempo, la sincronización automática del clima, el cifrado bcrypt y los tokens JWT, la validación de entradas en el servidor y la ausencia total de borrado físico de registros.
A41: Designación del especialista: asegurador de calidad.
A42: Categoría de Gestión | B42: Información del Perfil | C42: Detalles de Autoridad y Supervisión
A43: Identificación | B43: Nombre: Kimder De Jesús | C43: Verifica y certifica la calidad del software en todas sus etapas.
A44: Linea de Mando | B44: Reporta a: Jefe del Proyecto – Marcelo Tapia | C44: Nivel de control y validación independiente del equipo de desarrollo.
A45: Supervisa Operativa | B45: Supervisa a: No aplica (rol de evaluación independiente) | C45: Rol de evaluación autónoma que coordina la corrección de defectos y la verificación de los RNF.
A46: Niveles de Autoridad del asegurador de calidad | B46: Responsabilidad Técnica: | C46: Diseña y ejecuta el plan de pruebas funcionales y no funcionales: planificador de cuatro pasos, filtrado por preferencias, informe y folio único, control de acceso por rol, sincronización climática y su degradación, y medición del tiempo de respuesta.
A48: Designación del especialista: jefe del proyecto.
A49: Categoría de Gestión | B49: Información del Perfil | C49: Detalles de Autoridad y Supervisión
A50: Identificación | B50: Nombre: Marcelo Tapia | C50: Responsable máximo de la planificación, ejecución y cierre del proyecto e interlocutor ante el MTC.
A51: Linea de Mando | B51: Reporta a: Dirección General del Ministerio de Transportes y Comunicaciones (MTC) | C51: Nivel estratégico superior que reporta avances, riesgos y decisiones críticas.
...

Sheet RES-RF-RNF
A2: Código: | C2: RT-2026-001
A3: Nombre del Proyecto | C3: Sistema Web de Rutas Turísticas Peatonales desde Estaciones Ferroviarias
A4: Versión: | C4: 1.0
A5: Fecha de la versión: | C5: 17 de agosto de 2026
A6: Consorcio: | C6: Ministerio de Transportes y Comunicaciones (MTC)
A7: Creado por: | C7: Marcelo Tapia (Jefe de Proyecto · Analista de Negocios)
C8: Ricardo Yanapa (Desarrollador)
A9: Aprobado por: | C9: Ing. Mg. Freddy Ferrari Fernández
A10: Nombre del archivo: | C10: DOC-REQ-RT-2026-001 – Norma IEEE 830 act. ISO/IEC/IEEE 29148.xlsx
A11: Nivel de confidencialidad: | C11: Media
A14: Cuadro Resumen de Contraste de Evaluación de Cumplimiento
A15: N° | B15: RF – CASO | C15: RF - CUMPLIDOS - EVIDENCIADO - PRODUCTO | D15: RNF – CASO | E15: RNF - CUMPLIDOS - EVIDENCIADO - PRODUCTO
A16: 1 | B16: RF01 — Consultar catálogo público de estaciones [Esencial] | C16: X | D16: RNF01 — La interfaz deberá ser web responsive y adaptarse a dispositivos móviles, con puntos de quiebre para teléfono, tableta y escritorio, sin desbordes horizontales desde 360 píxeles de ancho. | E16: X
A17: 2 | B17: RF02 — Consultar zonas turísticas por estación [Esencial] | C17: X | D17: RNF02 — El tiempo de respuesta de cada consulta deberá ser menor a 2 segundos en condiciones normales de operación. | E17: X
A18: 3 | B18: RF03 — Registrar preferencias turísticas [Esencial] | C18: X | D18: RNF03 — La previsión climática y los datos ferroviarios deberán actualizarse diariamente; la sincronización climática se ejecutará a las 05:00 hora de Lima, antes del primer servicio del día. | E18: X
A19: 4 | B19: RF04 — Seleccionar estación de partida [Esencial] | C19: X | D19: RNF04 — La interfaz deberá ser amigable y accesible: contraste suficiente, textos alternativos en las imágenes y navegación operable por teclado. | E19: X
A20: 5 | B20: RF05 — Listar alternativas compatibles [Esencial] | C20: X | D20: RNF05 — Las contraseñas deberán almacenarse cifradas con bcrypt y no exponerse fuera del backend; la sesión del panel se sostendrá con tokens JWT con expiración. | E20: X
A21: 6 | B21: RF06 — Calcular la ruta peatonal de ida y vuelta [Esencial] | C21: X | D21: RNF06 — La autorización por rol deberá verificarse siempre en el servidor; ocultar una opción del menú no se considerará una medida de seguridad. | E21: X
A22: 7 | B22: RF07 — Consultar el pronóstico climático [Esencial] | C22: X | D22: RNF07 — Toda entrada del usuario deberá validarse en el servidor antes de tocar la base de datos, con mensajes de error por campo. | E22: X
A23: 8 | B23: RF08 — Sincronizar automáticamente el clima [Esencial] | C23: X | D23: RNF08 — La base de datos deberá estar normalizada hasta la tercera forma normal sobre el motor InnoDB, con claves foráneas y sin ninguna operación de borrado físico. | E23: X
A24: 9 | B24: RF09 — Generar el informe turístico consolidado [Esencial] | C24: X | D24: RNF09 — Ante la indisponibilidad del proveedor externo de clima, el sistema deberá degradar de forma elegante y emitir el informe sin el bloque meteorológico, sin interrumpir el servicio. | E24: X
A25: 10 | B25: RF10 — Recuperar un informe por su código [Esencial] | C25: X | D25: RNF10 — El planificador deberá guiar al ciudadano en cuatro pasos con avance controlado, impidiendo el acceso a un paso sin haber completado el anterior. | E25: X
A26: 11 | B26: RF11 — Autenticar a los operadores del panel [Esencial] | C26: X | D26: RNF11 — El código deberá organizarse en capas —rutas, controladores, servicios, middlewares y utilidades— y la base de datos deberá aplicar una convención de prefijos por dominio. | E26: X
A27: 12 | B27: RF12 — Controlar el acceso por rol [Esencial] | C27: X | D27: RNF12 — La plataforma deberá operar en los navegadores modernos vigentes y desplegarse sobre Node.js 20 o superior y MySQL 8 o superior. | E27: X
... A29: 14 | B29: RF14 — Administrar servicios, horarios y tarifas [Esencial] | C29: X | D29: RNF14 — El sistema deberá operar en español de Perú, con zona horaria America/Lima y montos expresados en soles (PEN). | E29: X
A30: 15 | B30: RF15 — Administrar zonas turísticas e hitos [Esencial] | C30: X
A31: 16 | B31: RF16 — Consultar estaciones en solo lectura [Esencial] | C31: X
A32: 17 | B32: RF17 — Publicar o retirar contenido público [Esencial] | C32: X
A33: 18 | B33: RF18 — Dar de baja y reactivar lógicamente [Esencial] | C33: X
A34: 19 | B34: RF19 — Validar los datos de entrada [Esencial] | C34: X
A35: 20 | B35: RF20 — Cargar imágenes de estaciones y zonas [Condicional] | C35: X
A36: 21 | B36: RF21 — Visualizar la ruta sobre un mapa [Condicional] | C36: X
A37: 22 | B37: RF22 — Exportar el informe a PDF [Opcional] | C37: X
A38: TOTAL | B38: =COUNTA(B16:B37) -> 22 | C38: =COUNTA(C16:C37) -> 22 | D38: =COUNTA(D16:D37) -> 14 | E38: =COUNTA(E16:E37) -> 14
B41: Restricción para evaluación: RF EVI > 50 %
B44: RF TOTAL | C44: RF EVI | D44: RNF TOTAL | E44: RNF EVI
B45: =B38 -> 22 | C45: =C38 -> 22 | D45: =D38 -> 14 | E45: =E38 -> 14
B46: =C45/B45 -> 1 | D46: =E45/D45 -> 1

Sheet TABLAS
B1: Adaptacion de | C1: ISO (Organización Internacional de Normalización)
C2: IEC (Comisión Electrotécnica Internacional)
C3: Instituto de Ingenieros Eléctricos y Electrónicos | E3: Se emplea el término 'Actualización' porque la norma IEEE 830 no desapareció conceptualmente, sino que evolucionó. El propio comité de la IEEE, junto con ISO, tomó la base de la 830 y la actualizó para crear la ISO/IEC/IEEE 29148, adaptándola a las necesidades de los sistemas complejos actuales. El proyecto RT-2026-001 refleja esa misma actualización metodológica sobre sus 22 requerimientos funcionales.
C4: Norma Base - IEEE - 830
C5: Actualizacion - ISO/IEC/IEEE 29148
C6: Recomendaciones prácticas para la especificacion de requerimientos
B8: Necesario | C8: El requerimiento ofrece a los stakeholders el valor de negocio esperado, diferencia el producto de otros del mercado o es necesario para adecuarse a una regulación externa. Ante la duda cabe preguntar: “¿qué sería lo peor de no incluirlo?”. Si no hay respuesta ni consecuencia, probablemente no sea necesario.
B9: Completo | C9: Un requerimiento está completo si no necesita ampliar detalles en su redacción, es decir, si proporciona la información suficiente para su comprensión.
B10: Consistente | C10: Un requerimiento es consistente si no contradice a otro requerimiento. Un ejemplo de contradicción es que el sistema de permisos autorice a un usuario a hacer algo que no está en su tabla de acceso.
B11: Singular | C11: Contiene una sola idea. El requerimiento provee una función o capacidad acorde con una necesidad de los stakeholders, evitando combinar varios requerimientos en un solo párrafo.
B12: No ambiguo | C12: El requerimiento está escrito con total claridad y precisión, de modo que posee una única interpretación posible para todos los lectores. No utiliza términos vagos ni subjetivos.
B13: Factible | C13: Es posible implementar el requerimiento dentro de las capacidades y limitaciones del sistema y del proyecto: se conoce el framework de desarrollo y se cuenta con el tiempo y el presupuesto necesarios.
B14: Verificable | C14: Debe ser posible comprobarlo por inspección, análisis, prueba o demostración. Al escribirlo se deben determinar sus criterios de aceptación; si no se puede comprobar, no se sabe si se cumplió.
B15: Modificable | C15: Que se pueda realizar alguna modificación sobre el requerimiento y que esta sea sencilla, consistente y completa.
B16: Rastreable | C16: La especificación se organiza de tal forma que cada función del sistema se pueda rastrear hasta su conjunto de requerimientos correspondiente. Facilita las pruebas y la validación del diseño.
C20: Procedemos igual con los demás criterios, teniendo en cuenta los reciprocos de cada calificación asignada:
C22: 10 puntos: Valor reciproco de 0.1. | E22: =1/10 -> 0.1
C23: 5 puntos: Valor reciproco de 0.2. | E23: =1/5 -> 0.2
C24: 1 punto: Valor reciproco de 1 punto. | E24: =1/1 -> 1
C25: 0.2 puntos: Valor reciproco de 5 puntos.
C26: 0.1 puntos: Valor reciproco de 10 puntos.
C28: La dinámica consiste en preguntarnos, si cada criterio de la fila es más o menos importante que el criterio de la columna. Recuerda que fila es a horizontal como columna es a vertical.
C30: 10: El criterio de fila es mucho más importante que el criterio de columna.
C31: 5: El criterio de fila es más importante que el criterio de columna.
C32: 1: Ambos criterios son igual de importantes.
C33: 0.2: El criterio de fila es menos importante que el criterio de columna.
C34: 0.1: El criterio de fila es mucho menos importante que el criterio de columna.
C37: Instrucciones: para completar la matriz, compare el criterio de la fila (horizontal) con el criterio de la columna (vertical). En cada casilla pregúntese: ¿qué tan importante es el criterio de la fila respecto al criterio de la columna? Si es mucho más importante, coloque 10; si es más importante, 5; si ambos tienen el mismo peso, 1; si es menos importante, 0.2; y si es mucho menos importante, 0.1. La celda simétrica toma siempre el valor recíproco. Cada celda de la hoja EVA lleva un comentario emergente que recuerda el significado de la puntuación introducida.

Sheet DETALLE-IEEE
A1: ¿Qué es la Norma IEEE-830? | D1: ¿Qué es la Norma ISO/IEC/IEEE 29148?
A2: Es un estándar internacional que define la forma correcta de redactar la Especificación de Requerimientos de Software (SRS). En lugar de escribir una lista de deseos, esta norma obliga a documentar cada detalle de forma que no existan dudas. | D2: Es el estándar internacional vigente que unifica y define los procesos para la Ingeniería de Requisitos en sistemas y software. En lugar de limitarse a una lista estática de deseos, esta norma establece una estructura modular obligatoria y una sintaxis formal que elimina por completo las ambigüedades técnicas.
A3: Característica | B3: Documentación Informal | C3: Norma IEEE-830 | D3: Norma ISO/IEC/IEEE 29148
A4: Claridad | B4: Sujeta a interpretaciones erróneas. | C4: Cada requisito es único e inequívoco. | D4: Se exige la regla de Singularidad (una sola idea por párrafo) y uso mandatorio de sintaxis formal ("El sistema deberá...") para erradicar cualquier ambigüedad.
A5: Validación | B5: Difícil de probar si se cumplió. | C5: Cada requisito debe ser verificable con pruebas. | D5: Cada requisito incluye criterios de aceptación explícitos y trazabilidad bidireccional automatizada hacia los casos de prueba desde el inicio
A6: Organización | B6: Datos dispersos en notas o correos. | C6: Estructura jerárquica estandarizada. | D6: Arquitectura modular por niveles de abstracción (Negocio/Usuario/Sistema).
A7: Autoridad | B7: Difícil de auditar o aprobar. | C7: Permite una aprobación formal por el Analista de Negocio. | D7: Proceso iterativo de gobernanza con aprobación conjunta de múltiples Stakeholders (Negocio, Desarrollo y Aseguramiento de Calidad) regulado por contratos globales.
